2023-04-08 20:M:s - root - ERROR 11_tracebackÄ£¿é: Traceback (most recent call last):
  File "D:\application\Python\python_code\Ä£¿é\11_tracebackÄ£¿é.py", line 21, in <module>
    print(1/0)
ZeroDivisionError: division by zero

